Workbook

Sheet 📊 Tableau de Bord
A1: NORMX Tax 2026 — Plan de Tests Fonctionnels
A2: NORMX AI SAS · Testeur : Christelle · Version 3.0 (Keycloak SSO + Schema PG + Landing Pennylane)
A4: Module | C4: Tests | D4: ✅ PASS | E4: ❌ FAIL | F4: ⚠️ PARTIEL | G4: ☐ À tester | H4: % Avancement | I4: Clé filtre
A5: 🔐 Authentification | B5: 🔐 | C5: 6 | D5: =COUNTIFS('🧪 Tests'!A:A,I5,'🧪 Tests'!G:G,"✅ PASS") | E5: =COUNTIFS('🧪 Tests'!A:A,I5,'🧪 Tests'!G:G,"❌ FAIL") | F5: =COUNTIFS('🧪 Tests'!A:A,I5,'🧪 Tests'!G:G,"⚠️ PARTIEL") | G5: =COUNTIFS('🧪 Tests'!A:A,I5,'🧪 Tests'!G:G,"☐ À tester") | H5: =IF(C5>0,ROUND((D5+F5*0.5)/C5*100,1)&"%","0%") | I5: Authentification
A6: 🏠 Accueil (Home) | B6: 🏠 | C6: 4 | D6: =COUNTIFS('🧪 Tests'!A:A,I6,'🧪 Tests'!G:G,"✅ PASS") | E6: =COUNTIFS('🧪 Tests'!A:A,I6,'🧪 Tests'!G:G,"❌ FAIL") | F6: =COUNTIFS('🧪 Tests'!A:A,I6,'🧪 Tests'!G:G,"⚠️ PARTIEL") | G6: =COUNTIFS('🧪 Tests'!A:A,I6,'🧪 Tests'!G:G,"☐ À tester") | H6: =IF(C6>0,ROUND((D6+F6*0.5)/C6*100,1)&"%","0%") | I6: Accueil (Home)
A7: 📖 Navigation CGI | B7: 📖 | C7: 13 | D7: =COUNTIFS('🧪 Tests'!A:A,I7,'🧪 Tests'!G:G,"✅ PASS") | E7: =COUNTIFS('🧪 Tests'!A:A,I7,'🧪 Tests'!G:G,"❌ FAIL") | F7: =COUNTIFS('🧪 Tests'!A:A,I7,'🧪 Tests'!G:G,"⚠️ PARTIEL") | G7: =COUNTIFS('🧪 Tests'!A:A,I7,'🧪 Tests'!G:G,"☐ À tester") | H7: =IF(C7>0,ROUND((D7+F7*0.5)/C7*100,1)&"%","0%") | I7: Navigation CGI
A8: 🔍 Recherche | B8: 🔍 | C8: 6 | D8: =COUNTIFS('🧪 Tests'!A:A,I8,'🧪 Tests'!G:G,"✅ PASS") | E8: =COUNTIFS('🧪 Tests'!A:A,I8,'🧪 Tests'!G:G,"❌ FAIL") | F8: =COUNTIFS('🧪 Tests'!A:A,I8,'🧪 Tests'!G:G,"⚠️ PARTIEL") | G8: =COUNTIFS('🧪 Tests'!A:A,I8,'🧪 Tests'!G:G,"☐ À tester") | H8: =IF(C8>0,ROUND((D8+F8*0.5)/C8*100,1)&"%","0%") | I8: Recherche
A9: 📊 Simulateurs | B9: 📊 | C9: 19 | D9: =COUNTIFS('🧪 Tests'!A:A,I9,'🧪 Tests'!G:G,"✅ PASS") | E9: =COUNTIFS('🧪 Tests'!A:A,I9,'🧪 Tests'!G:G,"❌ FAIL") | F9: =COUNTIFS('🧪 Tests'!A:A,I9,'🧪 Tests'!G:G,"⚠️ PARTIEL") | G9: =COUNTIFS('🧪 Tests'!A:A,I9,'🧪 Tests'!G:G,"☐ À tester") | H9: =IF(C9>0,ROUND((D9+F9*0.5)/C9*100,1)&"%","0%") | I9: Simulateurs
A10: 🤖 Assistant IA | B10: 🤖 | C10: 12 | D10: =COUNTIFS('🧪 Tests'!A:A,I10,'🧪 Tests'!G:G,"✅ PASS") | E10: =COUNTIFS('🧪 Tests'!A:A,I10,'🧪 Tests'!G:G,"❌ FAIL") | F10: =COUNTIFS('🧪 Tests'!A:A,I10,'🧪 Tests'!G:G,"⚠️ PARTIEL") | G10: =COUNTIFS('🧪 Tests'!A:A,I10,'🧪 Tests'!G:G,"☐ À tester") | H10: =IF(C10>0,ROUND((D10+F10*0.5)/C10*100,1)&"%","0%") | I10: Assistant IA
A11: 📅 Calendrier Fiscal | B11: 📅 | C11: 4 | D11: =COUNTIFS('🧪 Tests'!A:A,I11,'🧪 Tests'!G:G,"✅ PASS") | E11: =COUNTIFS('🧪 Tests'!A:A,I11,'🧪 Tests'!G:G,"❌ FAIL") | F11: =COUNTIFS('🧪 Tests'!A:A,I11,'🧪 Tests'!G:G,"⚠️ PARTIEL") | G11: =COUNTIFS('🧪 Tests'!A:A,I11,'🧪 Tests'!G:G,"☐ À tester") | H11: =IF(C11>0,ROUND((D11+F11*0.5)/C11*100,1)&"%","0%") | I11: Calendrier Fiscal
A12: 👤 Profil & Abonnement | B12: 👤 | C12: 7 | D12: =COUNTIFS('🧪 Tests'!A:A,I12,'🧪 Tests'!G:G,"✅ PASS") | E12: =COUNTIFS('🧪 Tests'!A:A,I12,'🧪 Tests'!G:G,"❌ FAIL") | F12: =COUNTIFS('🧪 Tests'!A:A,I12,'🧪 Tests'!G:G,"⚠️ PARTIEL") | G12: =COUNTIFS('🧪 Tests'!A:A,I12,'🧪 Tests'!G:G,"☐ À tester") | H12: =IF(C12>0,ROUND((D12+F12*0.5)/C12*100,1)&"%","0%") | I12: Profil & Abonnement
A13: 🔓 FREE Trial | B13: 🔓 | C13: 4 | D13: =COUNTIFS('🧪 Tests'!A:A,I13,'🧪 Tests'!G:G,"✅ PASS") | E13: =COUNTIFS('🧪 Tests'!A:A,I13,'🧪 Tests'!G:G,"❌ FAIL") | F13: =COUNTIFS('🧪 Tests'!A:A,I13,'🧪 Tests'!G:G,"⚠️ PARTIEL") | G13: =COUNTIFS('🧪 Tests'!A:A,I13,'🧪 Tests'!G:G,"☐ À tester") | H13: =IF(C13>0,ROUND((D13+F13*0.5)/C13*100,1)&"%","0%") | I13: FREE Trial
A14: ⚡ Performance | B14: ⚡ | C14: 8 | D14: =COUNTIFS('🧪 Tests'!A:A,I14,'🧪 Tests'!G:G,"✅ PASS") | E14: =COUNTIFS('🧪 Tests'!A:A,I14,'🧪 Tests'!G:G,"❌ FAIL") | F14: =COUNTIFS('🧪 Tests'!A:A,I14,'🧪 Tests'!G:G,"⚠️ PARTIEL") | G14: =COUNTIFS('🧪 Tests'!A:A,I14,'🧪 Tests'!G:G,"☐ À tester") | H14: =IF(C14>0,ROUND((D14+F14*0.5)/C14*100,1)&"%","0%") | I14: Performance
A15: 📱 UX Mobile | B15: 📱 | C15: 6 | D15: =COUNTIFS('🧪 Tests'!A:A,I15,'🧪 Tests'!G:G,"✅ PASS") | E15: =COUNTIFS('🧪 Tests'!A:A,I15,'🧪 Tests'!G:G,"❌ FAIL") | F15: =COUNTIFS('🧪 Tests'!A:A,I15,'🧪 Tests'!G:G,"⚠️ PARTIEL") | G15: =COUNTIFS('🧪 Tests'!A:A,I15,'🧪 Tests'!G:G,"☐ À tester") | H15: =IF(C15>0,ROUND((D15+F15*0.5)/C15*100,1)&"%","0%") | I15: UX Mobile
A16: 📖 Navigation Social | B16: 📖 | C16: 8 | D16: =COUNTIFS('🧪 Tests'!A:A,I16,'🧪 Tests'!G:G,"✅ PASS") | E16: =COUNTIFS('🧪 Tests'!A:A,I16,'🧪 Tests'!G:G,"❌ FAIL") | F16: =COUNTIFS('🧪 Tests'!A:A,I16,'🧪 Tests'!G:G,"⚠️ PARTIEL") | G16: =COUNTIFS('🧪 Tests'!A:A,I16,'🧪 Tests'!G:G,"☐ À tester") | H16: =IF(C16>0,ROUND((D16+F16*0.5)/C16*100,1)&"%","0%") | I16: Navigation Social
... A25: 📊 Dashboard | B25: 📊 | C25: 3 | D25: =COUNTIFS('🧪 Tests'!A:A,I25,'🧪 Tests'!G:G,"✅ PASS") | E25: =COUNTIFS('🧪 Tests'!A:A,I25,'🧪 Tests'!G:G,"❌ FAIL") | F25: =COUNTIFS('🧪 Tests'!A:A,I25,'🧪 Tests'!G:G,"⚠️ PARTIEL") | G25: =COUNTIFS('🧪 Tests'!A:A,I25,'🧪 Tests'!G:G,"☐ À tester") | H25: =IF(C25>0,ROUND((D25+F25*0.5)/C25*100,1)&"%","0%") | I25: Dashboard
A26: 📊 TOTAL GÉNÉRAL | C26: =SUM(C5:C25) | D26: =COUNTIF('🧪 Tests'!G:G,"✅ PASS") | E26: =COUNTIF('🧪 Tests'!G:G,"❌ FAIL") | F26: =COUNTIF('🧪 Tests'!G:G,"⚠️ PARTIEL") | G26: =COUNTIF('🧪 Tests'!G:G,"☐ À tester") | H26: =IF(C22>0,ROUND((D22+F22*0.5)/C22*100,1)&"%","0%")
A28: LÉGENDE DES STATUTS
A29: ☐ À tester | B29: Test non encore exécuté
A30: ✅ PASS | B30: Test réussi — comportement conforme
A31: ❌ FAIL | B31: Test échoué — bug à corriger
A32: ⚠️ PARTIEL | B32: Test partiellement réussi — à surveiller
A33: 🚫 N/A | B33: Test non applicable dans ce contexte
A36: ✅ CRITÈRES MISE EN PRODUCTION
A37: Minimum requis | B37: 100% des tests CRITIQUE en PASS ou N/A
A38: Recommandé | B38: 80% de tous les tests en PASS
A39: Aucun bug BLOQUANT | B39: Tous les bugs BLOQUANT doivent être CORRIGÉ avant lancement

Sheet 🧪 Tests
A1: NORMX Tax 2026 — Grille de Tests Fonctionnels Interactive
A2: Modifiez la colonne STATUT avec la liste déroulante · Version 3.0 (Keycloak SSO + Schema PG + Landing Pennylane)
A3: MODULE | B3: ID TEST | C3: DESCRIPTION | D3: ACTIONS À EFFECTUER | E3: RÉSULTAT ATTENDU | F3: PRIORITÉ | G3: STATUT | H3: DATE TEST | I3: 🐛 COMMENTAIRE / BUG | J3: 💡 BESOIN D'ÉVOLUTION | K3: TESTÉ PAR
A4: Authentification | B4: AUTH-01 | C4: Inscription via Keycloak SSO | D4: Accéder à tax.normx-ai.com → Cliquer 'Créer un compte' → Formulaire Keycloak | E4: Compte créé sur auth.normx-ai.com, OTP email envoyé, redirection vers l'app | F4: CRITIQUE | G4: ☐ À tester
A5: Authentification | B5: AUTH-02 | C5: Connexion Keycloak SSO | D5: Accéder à tax.normx-ai.com → 'Se connecter' → Identifiants Keycloak | E5: Token JWT reçu, accès dashboard, nom affiché, token stocké en localStorage | F5: CRITIQUE | G5: ☐ À tester
A6: Authentification | B6: AUTH-03 | C6: Brute force protection Keycloak | D6: Entrer un mot de passe erroné 5 fois de suite sur auth.normx-ai.com | E6: Compte temporairement bloqué par Keycloak, message d'erreur clair | F6: HAUTE | G6: ☐ À tester
A7: Authentification | B7: AUTH-04 | C7: Réinitialisation mot de passe Keycloak | D7: Cliquer 'Mot de passe oublié' sur auth.normx-ai.com → saisir email | E7: Email de réinitialisation envoyé via Keycloak SMTP | F7: HAUTE | G7: ☐ À tester
A8: Authentification | B8: AUTH-05 | C8: Déconnexion Keycloak | D8: Menu profil → Déconnexion | E8: Session Keycloak fermée, tokens supprimés, retour landing page | F8: NORMALE | G8: ☐ À tester
A9: Authentification | B9: AUTH-06 | C9: Accès protégé sans token | D9: Accéder directement à une URL API sans token Bearer | E9: 401 Unauthorized, redirection vers login Keycloak | F9: HAUTE | G9: ☐ À tester
A10: Accueil (Home) | B10: HOME-01 | C10: Affichage tableau de bord | D10: Se connecter et observer l'écran Home | E10: Accueil avec stats, codes CGI+Social, actions rapides, échéances fiscales | F10: HAUTE | G10: ☐ À tester
A11: Accueil (Home) | B11: HOME-02 | C11: Raccourcis de navigation fonctionnels | D11: Tapper les raccourcis (CGI, Social, IA, Simul) | E11: Chaque raccourci ouvre le bon module sans délai | F11: HAUTE | G11: ☐ À tester
A12: Accueil (Home) | B12: HOME-03 | C12: Historique des consultations récentes | D12: Consulter 3 articles → Revenir à l'accueil | E12: Les 3 articles apparaissent dans 'Dernières consultations' | F12: NORMALE | G12: ☐ À tester
A13: Accueil (Home) | B13: HOME-04 | C13: Alerte prochaine échéance fiscale | D13: Observer la carte d'échéance sur l'accueil | E13: Échéance fiscale la plus proche affichée | F13: NORMALE | G13: ☐ À tester
A14: Navigation CGI | B14: CGI-01 | C14: Navigation Tome → Titre → Chapitre → Article | D14: Taper sur Tome 1 → Titre I (ITS) → Chapitre 1 → Article 1 | E14: Arborescence complète parcourue, contenu article affiché | F14: CRITIQUE | G14: ☐ À tester
A15: Navigation CGI | B15: CGI-02 | C15: Affichage complet d'un article | D15: Ouvrir n'importe quel article du CGI | E15: Numéro, titre, texte intégral lisible | F15: CRITIQUE | G15: ☐ À tester
... A140: Dashboard | B140: DASH-03 | C140: Thème cohérent or/bleu | D140: Naviguer dans l'application | E140: Couleurs uniformes : or (#D4A843), bleu marine (#1A3A5C) | F140: NORMALE | G140: ☐ À tester

Sheet 🐛 Bugs & Évolutions
A1: NORMX Tax 2026 — Registre des Bugs & Besoins d'Évolution
A2: Consignez ici tous les bugs détectés et besoins d'amélioration identifiés pendant les tests
A3: # | B3: ID Test | C3: Module | D3: Description du problème | E3: Comportement observé / Détail | F3: Type | G3: Priorité | H3: Statut résolution | I3: Date détection
A4: =IF(B4<>"",1,"")
A5: =IF(B5<>"",2,"")
A6: =IF(B6<>"",3,"")
A7: =IF(B7<>"",4,"")
A8: =IF(B8<>"",5,"")
A9: =IF(B9<>"",6,"")
A10: =IF(B10<>"",7,"")
A11: =IF(B11<>"",8,"")
A12: =IF(B12<>"",9,"")
A13: =IF(B13<>"",10,"")
A14: =IF(B14<>"",11,"")
A15: =IF(B15<>"",12,"")
A16: =IF(B16<>"",13,"")
A17: =IF(B17<>"",14,"")
A18: =IF(B18<>"",15,"")
A19: =IF(B19<>"",16,"")
A20: =IF(B20<>"",17,"")
A21: =IF(B21<>"",18,"")
A22: =IF(B22<>"",19,"")
A23: =IF(B23<>"",20,"")
A24: =IF(B24<>"",21,"")
A25: =IF(B25<>"",22,"")
A26: =IF(B26<>"",23,"")
A27: =IF(B27<>"",24,"")
A28: =IF(B28<>"",25,"")
A29: =IF(B29<>"",26,"")
A30: =IF(B30<>"",27,"")
A31: =IF(B31<>"",28,"")
A32: =IF(B32<>"",29,"")
A33: =IF(B33<>"",30,"")
A34: =IF(B34<>"",31,"")
A35: =IF(B35<>"",32,"")
A36: =IF(B36<>"",33,"")
A37: =IF(B37<>"",34,"")
A38: =IF(B38<>"",35,"")
A39: =IF(B39<>"",36,"")
A40: =IF(B40<>"",37,"")
...

Sheet 📘 Guide
A1: NORMX Tax 2026 — Guide d'utilisation du fichier de tests
A3: 🎯 COMMENT UTILISER CE FICHIER
B4: 1. Aller dans la feuille '🧪 Tests' | C4: C'est ici que vous exécutez les tests un par un
B5: 2. Lire les colonnes D et E | C5: Actions à effectuer et résultat attendu
B6: 3. Changer le STATUT (colonne G) | C6: Cliquer → choisir dans la liste déroulante
B7: 4. Remplir la date de test (colonne H) | C7: Date d'exécution du test
B8: 5. Écrire les bugs (colonne I) | C8: Décrivez le problème si FAIL ou PARTIEL
B9: 6. Écrire les évolutions (colonne J) | C9: Idée d'amélioration ou fonctionnalité manquante
B10: 7. Consulter le Tableau de Bord | C10: Se met à jour automatiquement
B11: 8. Reporter les bugs dans '🐛 Bugs' | C11: Registre dédié avec priorités
A13: 📊 TABLEAU DE BORD
B14: Mise à jour automatique | C14: Compteurs PASS/FAIL/PARTIEL en temps réel
B15: % Avancement | C15: PASS + PARTIEL × 50%
B16: 17 modules | C16: 11 fiscaux + 6 sociaux
A18: 🔵 CODES PRIORITÉ
B19: CRITIQUE | C19: À tester en PREMIER — bloque la production si FAIL
B20: HAUTE | C20: À tester avant la mise en production
B21: NORMALE | C21: Tests complets
B22: BASSE | C22: Peut être testé après la production
A24: ✅ CRITÈRES MISE EN PRODUCTION
B25: Minimum requis | C25: 100% des tests CRITIQUE en PASS ou N/A
B26: Recommandé | C26: 80% de tous les tests en PASS
B27: Aucun bug BLOQUANT | C27: Tous résolus avant lancement
